Traceback (most recent call last):
  File "/usr/local/lib/python3.7/dist-packages/jupyter_cache/executors/utils.py", line 56, in single_nb_execution
    record_timing=False,
  File "/usr/local/lib/python3.7/dist-packages/nbclient/client.py", line 1204, in execute
    return NotebookClient(nb=nb, resources=resources, km=km, **kwargs).execute()
  File "/usr/local/lib/python3.7/dist-packages/nbclient/util.py", line 84, in wrapped
    return just_run(coro(*args, **kwargs))
  File "/usr/local/lib/python3.7/dist-packages/nbclient/util.py", line 62, in just_run
    return loop.run_until_complete(coro)
  File "/usr/lib/python3.7/asyncio/base_events.py", line 587, in run_until_complete
    return future.result()
  File "/usr/local/lib/python3.7/dist-packages/nbclient/client.py", line 664, in async_execute
    cell, index, execution_count=self.code_cells_executed + 1
  File "/usr/local/lib/python3.7/dist-packages/nbclient/client.py", line 965, in async_execute_cell
    await self._check_raise_for_error(cell, cell_index, exec_reply)
  File "/usr/local/lib/python3.7/dist-packages/nbclient/client.py", line 862, in _check_raise_for_error
    raise CellExecutionError.from_cell_and_msg(cell, exec_reply_content)
nbclient.exceptions.CellExecutionError: An error occurred while executing the following cell:
------------------
# information gain (entropy data target and entropy_data_target_1)
count_gain(entropy_data_target_1, target_data_baru_1)
------------------

[0;31m[0m
[0;31mNameError[0mTraceback (most recent call last)
[0;32m<ipython-input-64-06d570c48694>[0m in [0;36m<module>[0;34m[0m
[1;32m      1[0m [0;31m# information gain (entropy data target and entropy_data_target_1)[0m[0;34m[0m[0;34m[0m[0;34m[0m[0m
[0;32m----> 2[0;31m [0mcount_gain[0m[0;34m([0m[0mentropy_data_target_1[0m[0;34m,[0m [0mtarget_data_baru_1[0m[0;34m)[0m[0;34m[0m[0;34m[0m[0m
[0m
[0;31mNameError[0m: name 'target_data_baru_1' is not defined
NameError: name 'target_data_baru_1' is not defined

